Workbook

Sheet Sheet1
A1: Bid Summary Sample Source Spreadsheet
A3: Project Name : | C3: DeLorean Time Machine | E3: PIN : | G3: OUTATIME
A4: Project Number : | C4: 88 | E4: Bid Opening Datetime : | G4: 31346.375
A5: Base Estimate : | C5: 2679565
A9: Company | C9: Estimate | D9: % of Base Estimate
A10: ACME | C10: =Sheet2!J48 -> 2286368 | D10: =Sheet2!J49 -> 0.85326088
A11: MomCorp | C11: =Sheet2!L48 -> 179790 | D11: =Sheet2!L49 -> 0.067096712
A12: Buy n Large | C12: =Sheet3!J48 -> 2188218 | D12: =Sheet3!J49 -> 0.8166318
A13: Pizza Planet | C13: =Sheet3!L48 -> 2687187 | D13: =Sheet3!L49 -> 1.0028445

Sheet Sheet2
A1: Bid Summary Sample Source Spreadsheet Project Name : DeLorean Time Machine Project Number : 88 PIN : OUTATIME Region : Region SW Bid Opening Datetime : 10/26/1985 9:00 AM | H1: Base Estimate | J1: Bidder : ACME | L1: Bidder : MomCorp
A7: Line No. | B7: Item No. | C7: Description | D7: Item Name | E7: Additive | F7: Qty | G7: Unit | H7: Unit Price | I7: Amount | J7: Unit Price | K7: Amount | L7: Unit Price | M7: Amount
B8: Base Vehicle and Core Power
A9: 1 | B9: 91538204 | D9: DMC-12 DeLorean (1981–1983 model) | F9: 1 | G9: Each | I9: 55000 | K9: 57000 | M9: 52000
A10: 2 | B10: 10475923 | D10: Heavy-Duty Suspension Upgrades | F10: 1 | G10: Each | I10: 1500 | K10: 1550 | M10: 1500
A11: 3 | B11: 63920185 | D11: Industrial Roll-bar and Cabin Fire Suppression Bottle: $750 | F11: 1 | G11: Each | I11: 750 | K11: 750 | M11: 725
B12: Subtotal | H12: =SUM(I9:I11) -> 57250 | J12: =SUM(K9:K11) -> 59300 | L12: =SUM(M9:M11) -> 54225
B13: Temporal & Electrical Systems
A14: 4 | B14: 34691208 | D14: Flux Capacitor | F14: 1 | G14: Each | I14: 50000 | K14: 55000 | M14: 52000
A15: 5 | B15: 89254316 | D15: Time Circuits (Dashboard LED readout & keypad) | F15: 1 | G15: Each | I15: 5000 | K15: 5000 | M15: 5000
A16: 6 | B16: 21078964 | D16: Time Circuit Activation Switch | F16: 1 | G16: Each | I16: 15 | K16: 15 | M16: 15
A17: 7 | B17: 67431502 | D17: Plutonium-powered Nuclear Reactor | F17: 1 | G17: Each | I17: 10000 | K17: 10000 | M17: 10000
A18: 8 | B18: 15893047 | D18: Plutonium Chamber / Radiation Scrubber casing | F18: 1 | G18: Each | I18: 350 | K18: 350 | M18: 350
A19: 9 | B19: 94021853 | D19: Refined Plutonium | F19: 1 | G19: Each | I19: 2500000 | K19: 2100000 | L19: STEAL | M19: 0
A20: 10 | B20: 31267490 | D20: Wormhole Emitter / Induction Coils | F20: 1 | G20: Each | I20: 4000 | K20: 3778 | M20: 4000
A21: 11 | B21: 50819236 | D21: Dash Relay Banks and Heatsinks | F21: 1 | G21: Each | I21: 1200 | K21: 1200 | M21: 1300
A22: 12 | B22: 72340198 | D22: Tachyon Pulse Conduits and Wiring Harnesses | F22: 1 | G22: Each | I22: 1200 | K22: 1200 | M22: 1200
B23: Subtotal | H23: =sum(I14:I22) -> 2571765 | J23: =sum(K14:K22) -> 2176543 | L23: =sum(M14:M22) -> 73865
B24: Exterior Gadetry & Wiring
A25: 13 | B25: 19284360 | D25: Overhead Switch Console | F25: 1 | G25: Each | I25: 1400 | K25: 1400 | M25: 1400
A26: 14 | B26: 60517482 | D26: Flexible Wiring Conduits | F26: 1 | G26: Each | I26: 300 | K26: 300 | M26: 300
A27: 15 | B27: 35489012 | D27: Aviation-grade Dash Gauges and Dials | F27: 1 | G27: Each | I27: 800 | K27: 800 | M27: 800
A28: 16 | B28: 79021465 | D28: Plutonium Chamber Vents and Exhaust Flaps | F28: 1 | G28: Each | I28: 600 | K28: 575 | M28: 600
A29: 17 | B29: 24890317 | D29: Aviation/Helicopter Turbine Blade Scraps | F29: 1 | G29: Each | I29: 2500 | K29: 2500 | M29: 2500
A30: 18 | B30: 51639408 | D30: Heavy-Duty Radar Discs / Antennae | F30: 1 | G30: Each | I30: 400 | K30: 400 | M30: 450
A31: 19 | B31: 90312647 | D31: "OUTATIME" California License Plate | F31: 1 | G31: Each | I31: 50 | K31: 50 | M31: 50
A32: 20 | B32: 42785019 | D32: Lightning Rod Assembly (1955 modification) | F32: 1 | G32: Each | I32: 300 | K32: 300 | M32: 300
A33: 21 | B33: 18390246 | D33: Sikorsky Helicopter Engine Exhaust Ducts | F33: 1 | G33: Each | I33: 4500 | K33: 4500 | M33: 4500
A34: 22 | B34: 69204813 | D34: Rear Deck Cooling Fan (Torin Blower) | F34: 1 | G34: Each | I34: 700 | K34: 700 | M34: 700
A35: 23 | B35: 30419258 | D35: Crossover Tubes and Heavy-Duty Manufactured Clamps | F35: 1 | G35: Each | I35: 800 | K35: 800 | M35: 900
B36: Subtotal | H36: =sum(I25:I35) -> 12350 | J36: =sum(K25:K35) -> 12325 | L36: =sum(M25:M35) -> 12500
B37: Future Upgrades (2015 Add-ons)
A38: 24 | B38: 23958104 | D38: Hover Conversion Undercarriage Thrusters: Anti-gravity flight capable | F38: 1 | G38: Each | I38: 10000 | K38: 10000 | M38: 10000
A39: 25 | B39: 56201947 | D39: Mr. Fusion mounting bracket & integration harness | F39: 1 | G39: Each | I39: 800 | K39: 800 | M39: 800
A40: 26 | B40: 41083925 | D40: Mr. Fusion Home Energy Reactor | F40: 1 | G40: Each | I40: 3000 | K40: 3000 | M40: 4000
A41: 27 | B41: 98710342 | D41: Digital Speedometer / 88 mph Audio Warning Alarm | F41: 1 | G41: Each | I41: 400 | K41: 400 | M41: 400
B42: Subtotal | H42: =sum(I38:I41) -> 14200 | J42: =sum(K38:K41) -> 14200 | L42: =sum(M38:M41) -> 15200
B43: Labor | F43: 1 | G43: Each
A44: 28 | B44: 32158094 | D44: Contract Time | F44: 400 | G44: day | H44: 60 day | I44: 24000 | J44: 60 day | K44: 24000 | L44: 60 day | M44: 24000
B45: Subtotal | H45: =sum(I44) -> 24000 | J45: =sum(K44) -> 24000 | L45: =sum(M44) -> 24000
...

Sheet Sheet3
A1: Bid Summary Sample Source Spreadsheet Project Name : DeLorean Time Machine Project Number : 88 PIN : OUTATIME Region : Region SW Bid Opening Datetime : 10/26/1985 9:00 AM | H1: Base Estimate | J1: Bidder : Buy N Large | L1: Bidder : Pizza Planet
A7: Line No. | B7: Item No. | C7: Description | D7: Item Name | E7: Additive | F7: Qty | G7: Unit | H7: Unit Price | I7: Amount | J7: Unit Price | K7: Amount | L7: Unit Price | M7: Amount
B8: Base Vehicle and Core Power
A9: 1 | B9: 91538204 | D9: DMC-12 DeLorean (1981–1983 model) | F9: 1 | G9: Each | I9: 55000 | K9: 57000 | M9: 58000
A10: 2 | B10: 10475923 | D10: Heavy-Duty Suspension Upgrades | F10: 1 | G10: Each | I10: 1500 | K10: 1550 | M10: 1500
A11: 3 | B11: 63920185 | D11: Industrial Roll-bar and Cabin Fire Suppression Bottle: $750 | F11: 1 | G11: Each | I11: 750 | K11: 750 | M11: 775
B12: Subtotal | H12: =SUM(I9:I11) -> 57250 | J12: =SUM(K9:K11) -> 59300 | L12: =SUM(M9:M11) -> 60275
B13: Temporal & Electrical Systems
A14: 4 | B14: 34691208 | D14: Flux Capacitor | F14: 1 | G14: Each | I14: 50000 | K14: 55000 | M14: 52000
A15: 5 | B15: 89254316 | D15: Time Circuits (Dashboard LED readout & keypad) | F15: 1 | G15: Each | I15: 5000 | K15: 5000 | M15: 5000
A16: 6 | B16: 21078964 | D16: Time Circuit Activation Switch | F16: 1 | G16: Each | I16: 15 | K16: 15 | M16: 15
A17: 7 | B17: 67431502 | D17: Plutonium-powered Nuclear Reactor | F17: 1 | G17: Each | I17: 10000 | K17: 10000 | M17: 11000
A18: 8 | B18: 15893047 | D18: Plutonium Chamber / Radiation Scrubber casing | F18: 1 | G18: Each | I18: 350 | K18: 350 | M18: 350
A19: 9 | B19: 94021853 | D19: Refined Plutonium | F19: 1 | G19: Each | I19: 2500000 | K19: 2000000 | M19: 2500000
A20: 10 | B20: 31267490 | D20: Wormhole Emitter / Induction Coils | F20: 1 | G20: Each | I20: 4000 | K20: 3778 | M20: 4000
A21: 11 | B21: 50819236 | D21: Dash Relay Banks and Heatsinks | F21: 1 | G21: Each | I21: 1200 | K21: 1200 | M21: 1300
A22: 12 | B22: 72340198 | D22: Tachyon Pulse Conduits and Wiring Harnesses | F22: 1 | G22: Each | I22: 1200 | K22: 1200 | M22: 1200
B23: Subtotal | H23: =sum(I14:I22) -> 2571765 | J23: =sum(K14:K22) -> 2076543 | L23: =sum(M14:M22) -> 2574865
B24: Exterior Gadetry & Wiring
A25: 13 | B25: 19284360 | D25: Overhead Switch Console | F25: 1 | G25: Each | I25: 1400 | K25: 1400 | M25: 1400
A26: 14 | B26: 60517482 | D26: Flexible Wiring Conduits | F26: 1 | G26: Each | I26: 300 | K26: 300 | M26: 400
A27: 15 | B27: 35489012 | D27: Aviation-grade Dash Gauges and Dials | F27: 1 | G27: Each | I27: 800 | K27: 800 | M27: 800
A28: 16 | B28: 79021465 | D28: Plutonium Chamber Vents and Exhaust Flaps | F28: 1 | G28: Each | I28: 600 | K28: 575 | M28: 600
A29: 17 | B29: 24890317 | D29: Aviation/Helicopter Turbine Blade Scraps | F29: 1 | G29: Each | I29: 2500 | K29: 3500 | M29: 2500
A30: 18 | B30: 51639408 | D30: Heavy-Duty Radar Discs / Antennae | F30: 1 | G30: Each | I30: 400 | K30: 400 | M30: 450
A31: 19 | B31: 90312647 | D31: "OUTATIME" California License Plate | F31: 1 | G31: Each | I31: 50 | K31: 50 | M31: 50
A32: 20 | B32: 42785019 | D32: Lightning Rod Assembly (1955 modification) | F32: 1 | G32: Each | I32: 300 | K32: 300 | M32: 450
A33: 21 | B33: 18390246 | D33: Sikorsky Helicopter Engine Exhaust Ducts | F33: 1 | G33: Each | I33: 4500 | K33: 4750 | M33: 4500
A34: 22 | B34: 69204813 | D34: Rear Deck Cooling Fan (Torin Blower) | F34: 1 | G34: Each | I34: 700 | K34: 700 | M34: 700
A35: 23 | B35: 30419258 | D35: Crossover Tubes and Heavy-Duty Manufactured Clamps | F35: 1 | G35: Each | I35: 800 | K35: 800 | M35: 997
B36: Subtotal | H36: =sum(I25:I35) -> 12350 | J36: =sum(K25:K35) -> 13575 | L36: =sum(M25:M35) -> 12847
B37: Future Upgrades (2015 Add-ons)
A38: 24 | B38: 23958104 | D38: Hover Conversion Undercarriage Thrusters: Anti-gravity flight capable | F38: 1 | G38: Each | I38: 10000 | K38: 10000 | M38: 10000
A39: 25 | B39: 56201947 | D39: Mr. Fusion mounting bracket & integration harness | F39: 1 | G39: Each | I39: 800 | K39: 800 | M39: 800
A40: 26 | B40: 41083925 | D40: Mr. Fusion Home Energy Reactor | F40: 1 | G40: Each | I40: 3000 | K40: 3600 | M40: 4000
A41: 27 | B41: 98710342 | D41: Digital Speedometer / 88 mph Audio Warning Alarm | F41: 1 | G41: Each | I41: 400 | K41: 400 | M41: 400
B42: Subtotal | H42: =sum(I38:I41) -> 14200 | J42: =sum(K38:K41) -> 14800 | L42: =sum(M38:M41) -> 15200
B43: Labor
A44: 28 | B44: 32158094 | D44: Contract Time | F44: 400 | G44: day | H44: 60 day | I44: 24000 | J44: 60 day | K44: 24000 | L44: 60 day | M44: 24000
B45: Subtotal | H45: =sum(I44) -> 24000 | J45: =sum(K44) -> 24000 | L45: =sum(M44) -> 24000
...
